2025-07-23 10:53:55,939 [ERROR] django.request - Internal Server Error: /major-equipment/1/fuel/create/
Traceback (most recent call last):
  File "C:\Users\Sebastian\.conda\envs\bomberos\lib\site-packages\django\template\base.py", line 510, in parse
    compile_func = self.tags[command]
KeyError: 'set'

During handling of the above exception, another exception occurred:

Traceback (most recent call last):
  File "C:\Users\Sebastian\.conda\envs\bomberos\lib\site-packages\django\core\handlers\exception.py", line 55, in inner
    response = get_response(request)
  File "C:\Users\Sebastian\.conda\envs\bomberos\lib\site-packages\django\core\handlers\base.py", line 197, in _get_response
    response = wrapped_callback(request, *callback_args, **callback_kwargs)
  File "C:\Users\Sebastian\.conda\envs\bomberos\lib\site-packages\django\contrib\auth\decorators.py", line 59, in _view_wrapper
    return view_func(request, *args, **kwargs)
  File "D:\bomberos_project\major_equipment\views.py", line 388, in view_create_fuel
    return render(request, 'major_equipment/fuel/fuel_form.html', {
  File "C:\Users\Sebastian\.conda\envs\bomberos\lib\site-packages\django\shortcuts.py", line 25, in render
    content = loader.render_to_string(template_name, context, request, using=using)
  File "C:\Users\Sebastian\.conda\envs\bomberos\lib\site-packages\django\template\loader.py", line 61, in render_to_string
    template = get_template(template_name, using=using)
  File "C:\Users\Sebastian\.conda\envs\bomberos\lib\site-packages\django\template\loader.py", line 15, in get_template
    return engine.get_template(template_name)
  File "C:\Users\Sebastian\.conda\envs\bomberos\lib\site-packages\django\template\backends\django.py", line 79, in get_template
    return Template(self.engine.get_template(template_name), self)
  File "C:\Users\Sebastian\.conda\envs\bomberos\lib\site-packages\django\template\engine.py", line 177, in get_template
    template, origin = self.find_template(template_name)
  File "C:\Users\Sebastian\.conda\envs\bomberos\lib\site-packages\django\template\engine.py", line 159, in find_template
    template = loader.get_template(name, skip=skip)
  File "C:\Users\Sebastian\.conda\envs\bomberos\lib\site-packages\django\template\loaders\cached.py", line 57, in get_template
    template = super().get_template(template_name, skip)
  File "C:\Users\Sebastian\.conda\envs\bomberos\lib\site-packages\django\template\loaders\base.py", line 28, in get_template
    return Template(
  File "C:\Users\Sebastian\.conda\envs\bomberos\lib\site-packages\django\template\base.py", line 154, in __init__
    self.nodelist = self.compile_nodelist()
  File "C:\Users\Sebastian\.conda\envs\bomberos\lib\site-packages\django\template\base.py", line 196, in compile_nodelist
    nodelist = parser.parse()
  File "C:\Users\Sebastian\.conda\envs\bomberos\lib\site-packages\django\template\base.py", line 518, in parse
    raise self.error(token, e)
  File "C:\Users\Sebastian\.conda\envs\bomberos\lib\site-packages\django\template\base.py", line 516, in parse
    compiled_result = compile_func(self, token)
  File "C:\Users\Sebastian\.conda\envs\bomberos\lib\site-packages\django\template\loader_tags.py", line 299, in do_extends
    nodelist = parser.parse()
  File "C:\Users\Sebastian\.conda\envs\bomberos\lib\site-packages\django\template\base.py", line 518, in parse
    raise self.error(token, e)
  File "C:\Users\Sebastian\.conda\envs\bomberos\lib\site-packages\django\template\base.py", line 516, in parse
    compiled_result = compile_func(self, token)
  File "C:\Users\Sebastian\.conda\envs\bomberos\lib\site-packages\django\template\loader_tags.py", line 234, in do_block
    nodelist = parser.parse(("endblock",))
  File "C:\Users\Sebastian\.conda\envs\bomberos\lib\site-packages\django\template\base.py", line 518, in parse
    raise self.error(token, e)
  File "C:\Users\Sebastian\.conda\envs\bomberos\lib\site-packages\django\template\base.py", line 516, in parse
    compiled_result = compile_func(self, token)
  File "C:\Users\Sebastian\.conda\envs\bomberos\lib\site-packages\django\template\defaulttags.py", line 962, in do_if
    nodelist = parser.parse(("elif", "else", "endif"))
  File "C:\Users\Sebastian\.conda\envs\bomberos\lib\site-packages\django\template\base.py", line 518, in parse
    raise self.error(token, e)
  File "C:\Users\Sebastian\.conda\envs\bomberos\lib\site-packages\django\template\base.py", line 516, in parse
    compiled_result = compile_func(self, token)
  File "C:\Users\Sebastian\.conda\envs\bomberos\lib\site-packages\django\template\defaulttags.py", line 862, in do_for
    nodelist_loop = parser.parse(
  File "C:\Users\Sebastian\.conda\envs\bomberos\lib\site-packages\django\template\base.py", line 518, in parse
    raise self.error(token, e)
  File "C:\Users\Sebastian\.conda\envs\bomberos\lib\site-packages\django\template\base.py", line 516, in parse
    compiled_result = compile_func(self, token)
  File "C:\Users\Sebastian\.conda\envs\bomberos\lib\site-packages\django\template\defaulttags.py", line 962, in do_if
    nodelist = parser.parse(("elif", "else", "endif"))
  File "C:\Users\Sebastian\.conda\envs\bomberos\lib\site-packages\django\template\base.py", line 512, in parse
    self.invalid_block_tag(token, command, parse_until)
  File "C:\Users\Sebastian\.conda\envs\bomberos\lib\site-packages\django\template\base.py", line 567, in invalid_block_tag
    raise self.error(
django.template.exceptions.TemplateSyntaxError: Invalid block tag on line 27: 'set', expected 'elif', 'else' or 'endif'. Did you forget to register or load this tag?
2025-07-23 10:53:55,947 [ERROR] django.server - "POST /major-equipment/1/fuel/create/ HTTP/1.1" 500 295152
2025-07-23 10:53:56,031 [WARNING] django.request - Not Found: /favicon.ico
2025-07-23 10:53:56,032 [WARNING] django.server - "GET /favicon.ico HTTP/1.1" 404 3719
2025-07-23 10:58:56,635 [ERROR] myapp - Error guardando FuelLog: IntegrityError('el valor nulo en la columna «author_id» de la relación «major_equipment_fuellog» viola la restricción de no nulo\nDETAIL:  La fila que falla contiene (9, 200, 2025-07-23 14:56:00+00, 1000.00, 1000, hola mundo, , 21210.00, 1, 1, null, f, t).\n')
Traceback (most recent call last):
  File "C:\Users\Sebastian\.conda\envs\bomberos\lib\site-packages\django\db\backends\utils.py", line 105, in _execute
    return self.cursor.execute(sql, params)
psycopg2.errors.NotNullViolation: el valor nulo en la columna «author_id» de la relación «major_equipment_fuellog» viola la restricción de no nulo
DETAIL:  La fila que falla contiene (9, 200, 2025-07-23 14:56:00+00, 1000.00, 1000, hola mundo, , 21210.00, 1, 1, null, f, t).


The above exception was the direct cause of the following exception:

Traceback (most recent call last):
  File "D:\bomberos_project\major_equipment\views.py", line 369, in view_create_fuel
    FuelLog.objects.create(
  File "C:\Users\Sebastian\.conda\envs\bomberos\lib\site-packages\django\db\models\manager.py", line 87, in manager_method
    return getattr(self.get_queryset(), name)(*args, **kwargs)
  File "C:\Users\Sebastian\.conda\envs\bomberos\lib\site-packages\django\db\models\query.py", line 663, in create
    obj.save(force_insert=True, using=self.db)
  File "C:\Users\Sebastian\.conda\envs\bomberos\lib\site-packages\django\db\models\base.py", line 902, in save
    self.save_base(
  File "C:\Users\Sebastian\.conda\envs\bomberos\lib\site-packages\django\db\models\base.py", line 1008, in save_base
    updated = self._save_table(
  File "C:\Users\Sebastian\.conda\envs\bomberos\lib\site-packages\django\db\models\base.py", line 1169, in _save_table
    results = self._do_insert(
  File "C:\Users\Sebastian\.conda\envs\bomberos\lib\site-packages\django\db\models\base.py", line 1210, in _do_insert
    return manager._insert(
  File "C:\Users\Sebastian\.conda\envs\bomberos\lib\site-packages\django\db\models\manager.py", line 87, in manager_method
    return getattr(self.get_queryset(), name)(*args, **kwargs)
  File "C:\Users\Sebastian\.conda\envs\bomberos\lib\site-packages\django\db\models\query.py", line 1868, in _insert
    return query.get_compiler(using=using).execute_sql(returning_fields)
  File "C:\Users\Sebastian\.conda\envs\bomberos\lib\site-packages\django\db\models\sql\compiler.py", line 1882, in execute_sql
    cursor.execute(sql, params)
  File "C:\Users\Sebastian\.conda\envs\bomberos\lib\site-packages\django\db\backends\utils.py", line 122, in execute
    return super().execute(sql, params)
  File "C:\Users\Sebastian\.conda\envs\bomberos\lib\site-packages\django\db\backends\utils.py", line 79, in execute
    return self._execute_with_wrappers(
  File "C:\Users\Sebastian\.conda\envs\bomberos\lib\site-packages\django\db\backends\utils.py", line 92, in _execute_with_wrappers
    return executor(sql, params, many, context)
  File "C:\Users\Sebastian\.conda\envs\bomberos\lib\site-packages\django\db\backends\utils.py", line 100, in _execute
    with self.db.wrap_database_errors:
  File "C:\Users\Sebastian\.conda\envs\bomberos\lib\site-packages\django\db\utils.py", line 91, in __exit__
    raise dj_exc_value.with_traceback(traceback) from exc_value
  File "C:\Users\Sebastian\.conda\envs\bomberos\lib\site-packages\django\db\backends\utils.py", line 105, in _execute
    return self.cursor.execute(sql, params)
django.db.utils.IntegrityError: el valor nulo en la columna «author_id» de la relación «major_equipment_fuellog» viola la restricción de no nulo
DETAIL:  La fila que falla contiene (9, 200, 2025-07-23 14:56:00+00, 1000.00, 1000, hola mundo, , 21210.00, 1, 1, null, f, t).

2025-07-23 11:01:28,805 [ERROR] myapp - Error guardando FuelLog: IntegrityError('llave duplicada viola restricción de unicidad «unique_guide_per_station»\nDETAIL:  Ya existe la llave (station_id, guide_number)=(1, 10).\n')
Traceback (most recent call last):
  File "C:\Users\Sebastian\.conda\envs\bomberos\lib\site-packages\django\db\backends\utils.py", line 105, in _execute
    return self.cursor.execute(sql, params)
psycopg2.errors.UniqueViolation: llave duplicada viola restricción de unicidad «unique_guide_per_station»
DETAIL:  Ya existe la llave (station_id, guide_number)=(1, 10).


The above exception was the direct cause of the following exception:

Traceback (most recent call last):
  File "D:\bomberos_project\major_equipment\views.py", line 369, in view_create_fuel
    FuelLog.objects.create(
  File "C:\Users\Sebastian\.conda\envs\bomberos\lib\site-packages\django\db\models\manager.py", line 87, in manager_method
    return getattr(self.get_queryset(), name)(*args, **kwargs)
  File "C:\Users\Sebastian\.conda\envs\bomberos\lib\site-packages\django\db\models\query.py", line 663, in create
    obj.save(force_insert=True, using=self.db)
  File "C:\Users\Sebastian\.conda\envs\bomberos\lib\site-packages\django\db\models\base.py", line 902, in save
    self.save_base(
  File "C:\Users\Sebastian\.conda\envs\bomberos\lib\site-packages\django\db\models\base.py", line 1008, in save_base
    updated = self._save_table(
  File "C:\Users\Sebastian\.conda\envs\bomberos\lib\site-packages\django\db\models\base.py", line 1169, in _save_table
    results = self._do_insert(
  File "C:\Users\Sebastian\.conda\envs\bomberos\lib\site-packages\django\db\models\base.py", line 1210, in _do_insert
    return manager._insert(
  File "C:\Users\Sebastian\.conda\envs\bomberos\lib\site-packages\django\db\models\manager.py", line 87, in manager_method
    return getattr(self.get_queryset(), name)(*args, **kwargs)
  File "C:\Users\Sebastian\.conda\envs\bomberos\lib\site-packages\django\db\models\query.py", line 1868, in _insert
    return query.get_compiler(using=using).execute_sql(returning_fields)
  File "C:\Users\Sebastian\.conda\envs\bomberos\lib\site-packages\django\db\models\sql\compiler.py", line 1882, in execute_sql
    cursor.execute(sql, params)
  File "C:\Users\Sebastian\.conda\envs\bomberos\lib\site-packages\django\db\backends\utils.py", line 122, in execute
    return super().execute(sql, params)
  File "C:\Users\Sebastian\.conda\envs\bomberos\lib\site-packages\django\db\backends\utils.py", line 79, in execute
    return self._execute_with_wrappers(
  File "C:\Users\Sebastian\.conda\envs\bomberos\lib\site-packages\django\db\backends\utils.py", line 92, in _execute_with_wrappers
    return executor(sql, params, many, context)
  File "C:\Users\Sebastian\.conda\envs\bomberos\lib\site-packages\django\db\backends\utils.py", line 100, in _execute
    with self.db.wrap_database_errors:
  File "C:\Users\Sebastian\.conda\envs\bomberos\lib\site-packages\django\db\utils.py", line 91, in __exit__
    raise dj_exc_value.with_traceback(traceback) from exc_value
  File "C:\Users\Sebastian\.conda\envs\bomberos\lib\site-packages\django\db\backends\utils.py", line 105, in _execute
    return self.cursor.execute(sql, params)
django.db.utils.IntegrityError: llave duplicada viola restricción de unicidad «unique_guide_per_station»
DETAIL:  Ya existe la llave (station_id, guide_number)=(1, 10).

2025-07-23 11:05:14,321 [WARNING] django.request - Not Found: /favicon.ico
2025-07-23 11:05:14,322 [WARNING] django.server - "GET /favicon.ico HTTP/1.1" 404 3719
